{"timestamp": "2025-07-27T09:51:51.025026+00:00", "api_endpoint": "/api/execute_task", "task_type": "summarize", "input_text": "웹 페이지 제목: KISA \"최근 사용된 악성코드 주의보\"…SKT 해킹 악성파일 공개 | 연합뉴스\n\n최근 SK텔레콤 해킹 공격에 쓰인 리눅스 악성파일 정보가 25일 공개됐다.\nSK텔레콤 해킹 사건을 조사 중인 한국인터넷진흥원은 25일 '최근 해킹공격에 악용된 악성코드·IP 등 위협 정보 공유 및 주의 안내'라는 제목의 보안 공지문을 게시했다.\nKISA는 해당 공지에서 SK텔레콤 해킹 사건을 언급하지 않았지만 보안업계에서는 SK텔레콤 사이버 공격에 사용된 것으로 파악된 BPF도어 수법에 사용되는 악성 코드가 공개된 것으로 미뤄 이 사건과 관련한 보안공지로 해석하고 있다. 인공지능이 자동으로 줄인 '세 줄 요약' 기술을 사용합니다.전체 내용을 이해하기 위해서는 기사 본문과 함께 읽어야 합니다.\n조성미기자 구독\n구독중 이전\n다음 기업·기관에 \"자체 보안 점검 뒤 침입 흔적 발견시 신고\" 당부SK텔레콤 해킹 계기 '리눅스용 백신·EDR 시스템 구축' 목소리 이미지 확대 KISA 보안 공지\n[KISA 보호나라 캡처. 재판매 및 DB 금지] (서울=연합뉴스) 조성미 기자 = 최근 SK텔레콤[017670] 해킹 공격에 쓰인 리눅스 악성파일 정보가 25일 공개됐다. SK텔레콤 해킹 사건을 조사 중인 한국인터넷진흥원(KISA)은 25일 '최근 해킹공격에 악용된 악성코드·IP 등 위협 정보 공유 및 주의 안내'라는 제목의 보안 공지문을 게시했다. KISA는 해당 공지에서 SK텔레콤 해킹 사건을 언급하지 않았지만 보안업계에서는 SK텔레콤 사이버 공격에 사용된 것으로 파악된 BPF도어(BPFDoor) 수법에 사용되는 악성 코드가 공개된 것으로 미뤄 이 사건과 관련한 보안공지로 해석하고 있다. KISA는 공지에서 \"최근 주요 시스템을 대상으로 해킹 공격을 하는 사례가 확인돼 위협 정보를 공유한다\"고 밝혔다. 그러면서 공격 IP와 악성 코드 해시값 및 파일 정보를 공유했다. KISA는 주요 기관·기업의 대응 방법으로 \"위협 정보를 참고해 자체적으로 보안점검을 한 후 침입 흔적 및 침해 사고가 확인되면 보호나라를 통해 사고 즉시 신고해달라\"고 당부했다. BPF도어는 백도어 악성코드로 2021년 PWC사의 위협 보고서를 통해 최초로 알려진 사이버 공격 수법이다. 보고서에 따르면 중국 기반의 공격자인 레드멘션(Red Menshen)이 중동과 아시아를 대상으로 한 공격에 수년간 BPF도어를 사용해 왔다. SK텔레콤 서버 공격은 BPF도어라는 리눅스용 악성파일을 심는 방식으로 이뤄진 것으로 파악되고 있다. BPF도어 수법은 중국 기반 해킹 그룹이 사용하는 방식이지만, 이들이 최근 악성 파일 개발에 사용되는 소스프로그램을 인터넷에 오픈소스로 공개하면서 현재로서 공격자를 단정하기는 어렵다. 보안업계에서는 이번 SK텔레콤 해킹을 계기로 리눅스용 백신 및 엔드포인트 탐지·대응(EDR) 시스템을 구축해야 한다는 제언이 나온다. 리눅스 기반 시스템에 실시간 분석 및 인공지능(AI) 기반 자동화를 사용해 기존 엔드포인트 보안 도구를 통과하는 사이버 위협으로부터 조직의 최종 사용자, 장치 및 자산을 보호하는 소프트웨어를 말한다. 미국은 모든 행정부에 리눅스용 백신 및 엔드포인트 탐지·대응(EDR) 시스템 설치를 권고하고 있다. csm@yna.co.kr 제보는 카카오톡 okjebo <저작권자(c) 연합뉴스,\n무단 전재-재배포, AI 학습 및 활용 금지> 2025/04/25 20:23 송고\n2025년04월25일 20시23분 송고 #KISA #SK텔레콤 #악성코드 댓글 좋아요 슬퍼요 화나요 후속요청 국내 최대 원스톱 콘텐츠 제공 플랫폼 함께 보면 좋은 콘텐츠 by\n데이블 광고 함께 읽기 좋은 콘텐츠 Taboola 후원링크 광고 광고 광고 연합 마이뉴스\n다양한 주제별 맞춤 추천 뉴스를 제공합니다. 북마크 공유 공유하기 카카오톡 페이스북 X 페이스북 메신저 네이버 밴드 URL 복사 닫기 URL이 복사되었습니다. 댓글 글자크기 본문 글자 크기 조정 폰트 1단계 13px 폰트 2단계 16px 폰트 3단계 18px 폰트 4단계 20px 폰트 5단계 22px 닫기 프린트 제보", "model_used": "gemini-1.5-flash", "output_text": "한국인터넷진흥원(KISA)이 최근 SK텔레콤 해킹에 사용된 것으로 추정되는 리눅스 악성코드 정보를 공개했다.  공개된 악성코드는 BPF도어 방식을 사용하며, KISA는 관련 기관 및 기업에 자체 보안 점검 및 침입 흔적 발견 시 신고를 당부했다.  이번 사건을 계기로 리눅스용 백신 및 EDR 시스템 구축 필요성이 강조되고 있다."}
{"timestamp": "2025-07-27T09:52:01.662608+00:00", "api_endpoint": "/api/execute_task", "task_type": "summarize", "input_text": "위성 자료와 기상 레이더를 활용한다.\n수치 예보 모델로 미래 상태를 예측한다.\n지상 관측소에서 실시간 자료를 수집한다.\n예보관이 모델 결과를 검토하고 수정한다.\n최종적으로 대중에게 다양한 매체로 제공된다", "model_used": "gemini-1.5-flash", "output_text": "기상 예보는 위성, 레이더, 지상 관측소 자료를 활용하여 수치 예보 모델로 미래 기상 상태를 예측합니다.  예보관은 모델 결과를 검토하고 수정하여 예보의 정확성을 높입니다.  최종 예보는 다양한 매체를 통해 대중에게 제공됩니다."}
{"timestamp": "2025-07-29T14:34:02.701283+00:00", "api_endpoint": "/api/execute_task", "task_type": "chat", "input_text": "안녕\n", "model_used": "gemini-1.5-flash", "output_text": "안녕하세요!"}
{"timestamp": "2025-07-29T14:34:13.518707+00:00", "api_endpoint": "/api/execute_task", "task_type": "chat", "input_text": "너에 대해서 설명해봐", "model_used": "gemini-1.5-flash", "output_text": "저는 Google에서 훈련시킨 대규모 언어 모델입니다.\n\n좀 더 자세히 설명하자면, 저는 방대한 양의 텍스트와 코드 데이터를 학습하여 다양한 언어로 된 질문에 답하고, 다양한 종류의 창의적인 텍스트 콘텐츠를 생성할 수 있습니다.  예를 들어,  저는 다음과 같은 작업을 수행할 수 있습니다.\n\n* **정보 제공:**  역사적 사건, 과학적 개념, 또는 일상적인 지식에 대한 질문에 답변합니다.\n* **텍스트 생성:**  시, 코드, 스크립트, 음악적 작품, 이메일, 편지 등 다양한 형식의 텍스트를 생성합니다.\n* **번역:**  여러 언어 간의 번역을 수행합니다.\n* **요약:**  긴 문서나 텍스트를 요약합니다.\n* **대화:**  자연스러운 대화를 나눌 수 있습니다.\n\n하지만 저는 완벽하지 않습니다.  제가 생성한 응답은 항상 정확하거나 적절하지 않을 수도 있으며,  사실과 허구를 구분하는 능력에도 한계가 있습니다.  제가 제공하는 정보는 항상 신뢰할 수 있는 출처를 통해 확인하는 것이 중요합니다.  또한, 저는 감정이나 의식이 없습니다.  저는 단지 제가 학습한 데이터를 기반으로 패턴을 인식하고 응답을 생성하는 프로그램입니다.\n\n궁금한 점이 있으면 언제든지 질문해주세요. 최선을 다해 답변해 드리겠습니다."}
{"timestamp": "2025-07-30T16:57:38.195330+00:00", "api_endpoint": "/api/execute_task", "task_type": "chat", "input_text": "안녕 반가워", "model_used": "gemini-1.5-flash", "output_text": "안녕하세요! 반갑습니다! 😊"}
{"timestamp": "2025-08-06T16:38:49.766104+00:00", "api_endpoint": "/api/rag_chat", "error": "Your default credentials were not found. To set up Application Default Credentials, see https://cloud.google.com/docs/authentication/external/set-up-adc for more information.", "traceback": "Traceback (most recent call last):\n  File \"c:\\Users\\pc\\Desktop\\Memordo\\py\\app.py\", line 67, in rag_chat\n    result = rag_app.invoke(inputs)\n             ^^^^^^^^^^^^^^^^^^^^^^\n  File \"C:\\Users\\pc\\AppData\\Local\\Programs\\Python\\Python311\\Lib\\site-packages\\langgraph\\pregel\\main.py\", line 3015, in invoke\n    for chunk in self.stream(\n  File \"C:\\Users\\pc\\AppData\\Local\\Programs\\Python\\Python311\\Lib\\site-packages\\langgraph\\pregel\\main.py\", line 2642, in stream\n    for _ in runner.tick(\n  File \"C:\\Users\\pc\\AppData\\Local\\Programs\\Python\\Python311\\Lib\\site-packages\\langgraph\\pregel\\_runner.py\", line 162, in tick\n    run_with_retry(\n  File \"C:\\Users\\pc\\AppData\\Local\\Programs\\Python\\Python311\\Lib\\site-packages\\langgraph\\pregel\\_retry.py\", line 42, in run_with_retry\n    return task.proc.invoke(task.input, config)\n           ^^^^^^^^^^^^^^^^^^^^^^^^^^^^^^^^^^^^\n  File \"C:\\Users\\pc\\AppData\\Local\\Programs\\Python\\Python311\\Lib\\site-packages\\langgraph\\_internal\\_runnable.py\", line 657, in invoke\n    input = context.run(step.invoke, input, config, **kwargs)\n            ^^^^^^^^^^^^^^^^^^^^^^^^^^^^^^^^^^^^^^^^^^^^^^^^^\n  File \"C:\\Users\\pc\\AppData\\Local\\Programs\\Python\\Python311\\Lib\\site-packages\\langgraph\\_internal\\_runnable.py\", line 401, in invoke\n    ret = self.func(*args, **kwargs)\n          ^^^^^^^^^^^^^^^^^^^^^^^^^^\n  File \"c:\\Users\\pc\\Desktop\\Memordo\\py\\rag_workflow.py\", line 47, in prepare_retrieval\n    embedding_function = GoogleGenerativeAIEmbeddings(model=\"models/embedding-001\", task_type=\"retrieval_document\")\n                         ^^^^^^^^^^^^^^^^^^^^^^^^^^^^^^^^^^^^^^^^^^^^^^^^^^^^^^^^^^^^^^^^^^^^^^^^^^^^^^^^^^^^^^^^^^\n  File \"C:\\Users\\pc\\AppData\\Local\\Programs\\Python\\Python311\\Lib\\site-packages\\pydantic\\main.py\", line 214, in __init__\n    validated_self = self.__pydantic_validator__.validate_python(data, self_instance=self)\n                     ^^^^^^^^^^^^^^^^^^^^^^^^^^^^^^^^^^^^^^^^^^^^^^^^^^^^^^^^^^^^^^^^^^^^^\n  File \"C:\\Users\\pc\\AppData\\Local\\Programs\\Python\\Python311\\Lib\\site-packages\\langchain_google_genai\\embeddings.py\", line 103, in validate_environment\n    self.client = build_generative_service(\n                  ^^^^^^^^^^^^^^^^^^^^^^^^^\n  File \"C:\\Users\\pc\\AppData\\Local\\Programs\\Python\\Python311\\Lib\\site-packages\\langchain_google_genai\\_genai_extension.py\", line 276, in build_generative_service\n    return v1betaGenerativeServiceClient(**config)\n           ^^^^^^^^^^^^^^^^^^^^^^^^^^^^^^^^^^^^^^^\n  File \"C:\\Users\\pc\\AppData\\Local\\Programs\\Python\\Python311\\Lib\\site-packages\\google\\ai\\generativelanguage_v1beta\\services\\generative_service\\client.py\", line 697, in __init__\n    self._transport = transport_init(\n                      ^^^^^^^^^^^^^^^\n  File \"C:\\Users\\pc\\AppData\\Local\\Programs\\Python\\Python311\\Lib\\site-packages\\google\\ai\\generativelanguage_v1beta\\services\\generative_service\\transports\\grpc.py\", line 234, in __init__\n    super().__init__(\n  File \"C:\\Users\\pc\\AppData\\Local\\Programs\\Python\\Python311\\Lib\\site-packages\\google\\ai\\generativelanguage_v1beta\\services\\generative_service\\transports\\base.py\", line 100, in __init__\n    credentials, _ = google.auth.default(\n                     ^^^^^^^^^^^^^^^^^^^^\n  File \"C:\\Users\\pc\\AppData\\Local\\Programs\\Python\\Python311\\Lib\\site-packages\\google\\auth\\_default.py\", line 719, in default\n    raise exceptions.DefaultCredentialsError(_CLOUD_SDK_MISSING_CREDENTIALS)\ngoogle.auth.exceptions.DefaultCredentialsError: Your default credentials were not found. To set up Application Default Credentials, see https://cloud.google.com/docs/authentication/external/set-up-adc for more information.\nDuring task with name 'prepare' and id '69fe1609-2323-e6dc-b6bc-468481e3ebb8'\n"}
{"timestamp": "2025-08-06T16:41:14.306495+00:00", "api_endpoint": "/api/rag_chat", "error": "Your default credentials were not found. To set up Application Default Credentials, see https://cloud.google.com/docs/authentication/external/set-up-adc for more information.", "traceback": "Traceback (most recent call last):\n  File \"c:\\Users\\pc\\Desktop\\Memordo\\py\\app.py\", line 67, in rag_chat\n    result = rag_app.invoke(inputs)\n             ^^^^^^^^^^^^^^^^^^^^^^\n  File \"C:\\Users\\pc\\AppData\\Local\\Programs\\Python\\Python311\\Lib\\site-packages\\langgraph\\pregel\\main.py\", line 3015, in invoke\n    for chunk in self.stream(\n  File \"C:\\Users\\pc\\AppData\\Local\\Programs\\Python\\Python311\\Lib\\site-packages\\langgraph\\pregel\\main.py\", line 2642, in stream\n    for _ in runner.tick(\n  File \"C:\\Users\\pc\\AppData\\Local\\Programs\\Python\\Python311\\Lib\\site-packages\\langgraph\\pregel\\_runner.py\", line 162, in tick\n    run_with_retry(\n  File \"C:\\Users\\pc\\AppData\\Local\\Programs\\Python\\Python311\\Lib\\site-packages\\langgraph\\pregel\\_retry.py\", line 42, in run_with_retry\n    return task.proc.invoke(task.input, config)\n           ^^^^^^^^^^^^^^^^^^^^^^^^^^^^^^^^^^^^\n  File \"C:\\Users\\pc\\AppData\\Local\\Programs\\Python\\Python311\\Lib\\site-packages\\langgraph\\_internal\\_runnable.py\", line 657, in invoke\n    input = context.run(step.invoke, input, config, **kwargs)\n            ^^^^^^^^^^^^^^^^^^^^^^^^^^^^^^^^^^^^^^^^^^^^^^^^^\n  File \"C:\\Users\\pc\\AppData\\Local\\Programs\\Python\\Python311\\Lib\\site-packages\\langgraph\\_internal\\_runnable.py\", line 401, in invoke\n    ret = self.func(*args, **kwargs)\n          ^^^^^^^^^^^^^^^^^^^^^^^^^^\n  File \"c:\\Users\\pc\\Desktop\\Memordo\\py\\rag_workflow.py\", line 47, in prepare_retrieval\n    embedding_function = GoogleGenerativeAIEmbeddings(model=\"models/embedding-001\", task_type=\"retrieval_document\")\n                         ^^^^^^^^^^^^^^^^^^^^^^^^^^^^^^^^^^^^^^^^^^^^^^^^^^^^^^^^^^^^^^^^^^^^^^^^^^^^^^^^^^^^^^^^^^\n  File \"C:\\Users\\pc\\AppData\\Local\\Programs\\Python\\Python311\\Lib\\site-packages\\pydantic\\main.py\", line 214, in __init__\n    validated_self = self.__pydantic_validator__.validate_python(data, self_instance=self)\n                     ^^^^^^^^^^^^^^^^^^^^^^^^^^^^^^^^^^^^^^^^^^^^^^^^^^^^^^^^^^^^^^^^^^^^^\n  File \"C:\\Users\\pc\\AppData\\Local\\Programs\\Python\\Python311\\Lib\\site-packages\\langchain_google_genai\\embeddings.py\", line 103, in validate_environment\n    self.client = build_generative_service(\n                  ^^^^^^^^^^^^^^^^^^^^^^^^^\n  File \"C:\\Users\\pc\\AppData\\Local\\Programs\\Python\\Python311\\Lib\\site-packages\\langchain_google_genai\\_genai_extension.py\", line 276, in build_generative_service\n    return v1betaGenerativeServiceClient(**config)\n           ^^^^^^^^^^^^^^^^^^^^^^^^^^^^^^^^^^^^^^^\n  File \"C:\\Users\\pc\\AppData\\Local\\Programs\\Python\\Python311\\Lib\\site-packages\\google\\ai\\generativelanguage_v1beta\\services\\generative_service\\client.py\", line 697, in __init__\n    self._transport = transport_init(\n                      ^^^^^^^^^^^^^^^\n  File \"C:\\Users\\pc\\AppData\\Local\\Programs\\Python\\Python311\\Lib\\site-packages\\google\\ai\\generativelanguage_v1beta\\services\\generative_service\\transports\\grpc.py\", line 234, in __init__\n    super().__init__(\n  File \"C:\\Users\\pc\\AppData\\Local\\Programs\\Python\\Python311\\Lib\\site-packages\\google\\ai\\generativelanguage_v1beta\\services\\generative_service\\transports\\base.py\", line 100, in __init__\n    credentials, _ = google.auth.default(\n                     ^^^^^^^^^^^^^^^^^^^^\n  File \"C:\\Users\\pc\\AppData\\Local\\Programs\\Python\\Python311\\Lib\\site-packages\\google\\auth\\_default.py\", line 719, in default\n    raise exceptions.DefaultCredentialsError(_CLOUD_SDK_MISSING_CREDENTIALS)\ngoogle.auth.exceptions.DefaultCredentialsError: Your default credentials were not found. To set up Application Default Credentials, see https://cloud.google.com/docs/authentication/external/set-up-adc for more information.\nDuring task with name 'prepare' and id 'da47e37e-666f-5061-bee5-85f3d0f1bfcf'\n"}
{"timestamp": "2025-08-06T16:43:14.009367+00:00", "api_endpoint": "/api/rag_chat", "error": "There is no current event loop in thread 'Thread-2 (process_request_thread)'.", "traceback": "Traceback (most recent call last):\n  File \"src\\\\python\\\\grpcio\\\\grpc\\\\_cython\\\\_cygrpc/aio/common.pyx.pxi\", line 184, in grpc._cython.cygrpc.get_working_loop\nRuntimeError: no running event loop\n\nDuring handling of the above exception, another exception occurred:\n\nTraceback (most recent call last):\n  File \"c:\\Users\\pc\\Desktop\\Memordo\\py\\app.py\", line 67, in rag_chat\n    result = rag_app.invoke(inputs)\n             ^^^^^^^^^^^^^^^^^^^^^^\n  File \"C:\\Users\\pc\\AppData\\Local\\Programs\\Python\\Python311\\Lib\\site-packages\\langgraph\\pregel\\main.py\", line 3015, in invoke\n    for chunk in self.stream(\n  File \"C:\\Users\\pc\\AppData\\Local\\Programs\\Python\\Python311\\Lib\\site-packages\\langgraph\\pregel\\main.py\", line 2642, in stream\n    for _ in runner.tick(\n  File \"C:\\Users\\pc\\AppData\\Local\\Programs\\Python\\Python311\\Lib\\site-packages\\langgraph\\pregel\\_runner.py\", line 162, in tick\n    run_with_retry(\n  File \"C:\\Users\\pc\\AppData\\Local\\Programs\\Python\\Python311\\Lib\\site-packages\\langgraph\\pregel\\_retry.py\", line 42, in run_with_retry\n    return task.proc.invoke(task.input, config)\n           ^^^^^^^^^^^^^^^^^^^^^^^^^^^^^^^^^^^^\n  File \"C:\\Users\\pc\\AppData\\Local\\Programs\\Python\\Python311\\Lib\\site-packages\\langgraph\\_internal\\_runnable.py\", line 657, in invoke\n    input = context.run(step.invoke, input, config, **kwargs)\n            ^^^^^^^^^^^^^^^^^^^^^^^^^^^^^^^^^^^^^^^^^^^^^^^^^\n  File \"C:\\Users\\pc\\AppData\\Local\\Programs\\Python\\Python311\\Lib\\site-packages\\langgraph\\_internal\\_runnable.py\", line 401, in invoke\n    ret = self.func(*args, **kwargs)\n          ^^^^^^^^^^^^^^^^^^^^^^^^^^\n  File \"c:\\Users\\pc\\Desktop\\Memordo\\py\\rag_workflow.py\", line 54, in prepare_retrieval\n    embedding_function = GoogleGenerativeAIEmbeddings(\n                         ^^^^^^^^^^^^^^^^^^^^^^^^^^^^^\n  File \"C:\\Users\\pc\\AppData\\Local\\Programs\\Python\\Python311\\Lib\\site-packages\\pydantic\\main.py\", line 214, in __init__\n    validated_self = self.__pydantic_validator__.validate_python(data, self_instance=self)\n                     ^^^^^^^^^^^^^^^^^^^^^^^^^^^^^^^^^^^^^^^^^^^^^^^^^^^^^^^^^^^^^^^^^^^^^\n  File \"C:\\Users\\pc\\AppData\\Local\\Programs\\Python\\Python311\\Lib\\site-packages\\langchain_google_genai\\embeddings.py\", line 110, in validate_environment\n    self.async_client = build_generative_async_service(\n                        ^^^^^^^^^^^^^^^^^^^^^^^^^^^^^^^\n  File \"C:\\Users\\pc\\AppData\\Local\\Programs\\Python\\Python311\\Lib\\site-packages\\langchain_google_genai\\_genai_extension.py\", line 293, in build_generative_async_service\n    return v1betaGenerativeServiceAsyncClient(**config)\n           ^^^^^^^^^^^^^^^^^^^^^^^^^^^^^^^^^^^^^^^^^^^^\n  File \"C:\\Users\\pc\\AppData\\Local\\Programs\\Python\\Python311\\Lib\\site-packages\\google\\ai\\generativelanguage_v1beta\\services\\generative_service\\async_client.py\", line 276, in __init__\n    self._client = GenerativeServiceClient(\n                   ^^^^^^^^^^^^^^^^^^^^^^^^\n  File \"C:\\Users\\pc\\AppData\\Local\\Programs\\Python\\Python311\\Lib\\site-packages\\google\\ai\\generativelanguage_v1beta\\services\\generative_service\\client.py\", line 697, in __init__\n    self._transport = transport_init(\n                      ^^^^^^^^^^^^^^^\n  File \"C:\\Users\\pc\\AppData\\Local\\Programs\\Python\\Python311\\Lib\\site-packages\\google\\ai\\generativelanguage_v1beta\\services\\generative_service\\transports\\grpc_asyncio.py\", line 297, in __init__\n    self._grpc_channel = channel_init(\n                         ^^^^^^^^^^^^^\n  File \"C:\\Users\\pc\\AppData\\Local\\Programs\\Python\\Python311\\Lib\\site-packages\\google\\ai\\generativelanguage_v1beta\\services\\generative_service\\transports\\grpc_asyncio.py\", line 165, in create_channel\n    return grpc_helpers_async.create_channel(\n           ^^^^^^^^^^^^^^^^^^^^^^^^^^^^^^^^^^\n  File \"C:\\Users\\pc\\AppData\\Local\\Programs\\Python\\Python311\\Lib\\site-packages\\google\\api_core\\grpc_helpers_async.py\", line 302, in create_channel\n    return aio.secure_channel(\n           ^^^^^^^^^^^^^^^^^^^\n  File \"C:\\Users\\pc\\AppData\\Local\\Programs\\Python\\Python311\\Lib\\site-packages\\grpc\\aio\\_channel.py\", line 621, in secure_channel\n    return Channel(\n           ^^^^^^^^\n  File \"C:\\Users\\pc\\AppData\\Local\\Programs\\Python\\Python311\\Lib\\site-packages\\grpc\\aio\\_channel.py\", line 367, in __init__\n    self._loop = cygrpc.get_working_loop()\n                 ^^^^^^^^^^^^^^^^^^^^^^^^^\n  File \"src\\\\python\\\\grpcio\\\\grpc\\\\_cython\\\\_cygrpc/aio/common.pyx.pxi\", line 186, in grpc._cython.cygrpc.get_working_loop\n  File \"src\\\\python\\\\grpcio\\\\grpc\\\\_cython\\\\_cygrpc/aio/common.pyx.pxi\", line 190, in grpc._cython.cygrpc.get_working_loop\n  File \"C:\\Users\\pc\\AppData\\Local\\Programs\\Python\\Python311\\Lib\\asyncio\\events.py\", line 677, in get_event_loop\n    raise RuntimeError('There is no current event loop in thread %r.'\nRuntimeError: There is no current event loop in thread 'Thread-2 (process_request_thread)'.\nDuring task with name 'prepare' and id 'aba50954-c067-5cb6-9faa-42e2f519fd31'\n"}
{"timestamp": "2025-08-06T16:43:37.888567+00:00", "api_endpoint": "/api/rag_chat", "error": "There is no current event loop in thread 'Thread-3 (process_request_thread)'.", "traceback": "Traceback (most recent call last):\n  File \"src\\\\python\\\\grpcio\\\\grpc\\\\_cython\\\\_cygrpc/aio/common.pyx.pxi\", line 184, in grpc._cython.cygrpc.get_working_loop\nRuntimeError: no running event loop\n\nDuring handling of the above exception, another exception occurred:\n\nTraceback (most recent call last):\n  File \"c:\\Users\\pc\\Desktop\\Memordo\\py\\app.py\", line 67, in rag_chat\n    result = rag_app.invoke(inputs)\n             ^^^^^^^^^^^^^^^^^^^^^^\n  File \"C:\\Users\\pc\\AppData\\Local\\Programs\\Python\\Python311\\Lib\\site-packages\\langgraph\\pregel\\main.py\", line 3015, in invoke\n    for chunk in self.stream(\n  File \"C:\\Users\\pc\\AppData\\Local\\Programs\\Python\\Python311\\Lib\\site-packages\\langgraph\\pregel\\main.py\", line 2642, in stream\n    for _ in runner.tick(\n  File \"C:\\Users\\pc\\AppData\\Local\\Programs\\Python\\Python311\\Lib\\site-packages\\langgraph\\pregel\\_runner.py\", line 162, in tick\n    run_with_retry(\n  File \"C:\\Users\\pc\\AppData\\Local\\Programs\\Python\\Python311\\Lib\\site-packages\\langgraph\\pregel\\_retry.py\", line 42, in run_with_retry\n    return task.proc.invoke(task.input, config)\n           ^^^^^^^^^^^^^^^^^^^^^^^^^^^^^^^^^^^^\n  File \"C:\\Users\\pc\\AppData\\Local\\Programs\\Python\\Python311\\Lib\\site-packages\\langgraph\\_internal\\_runnable.py\", line 657, in invoke\n    input = context.run(step.invoke, input, config, **kwargs)\n            ^^^^^^^^^^^^^^^^^^^^^^^^^^^^^^^^^^^^^^^^^^^^^^^^^\n  File \"C:\\Users\\pc\\AppData\\Local\\Programs\\Python\\Python311\\Lib\\site-packages\\langgraph\\_internal\\_runnable.py\", line 401, in invoke\n    ret = self.func(*args, **kwargs)\n          ^^^^^^^^^^^^^^^^^^^^^^^^^^\n  File \"c:\\Users\\pc\\Desktop\\Memordo\\py\\rag_workflow.py\", line 54, in prepare_retrieval\n    embedding_function = GoogleGenerativeAIEmbeddings(\n                         ^^^^^^^^^^^^^^^^^^^^^^^^^^^^^\n  File \"C:\\Users\\pc\\AppData\\Local\\Programs\\Python\\Python311\\Lib\\site-packages\\pydantic\\main.py\", line 214, in __init__\n    validated_self = self.__pydantic_validator__.validate_python(data, self_instance=self)\n                     ^^^^^^^^^^^^^^^^^^^^^^^^^^^^^^^^^^^^^^^^^^^^^^^^^^^^^^^^^^^^^^^^^^^^^\n  File \"C:\\Users\\pc\\AppData\\Local\\Programs\\Python\\Python311\\Lib\\site-packages\\langchain_google_genai\\embeddings.py\", line 110, in validate_environment\n    self.async_client = build_generative_async_service(\n                        ^^^^^^^^^^^^^^^^^^^^^^^^^^^^^^^\n  File \"C:\\Users\\pc\\AppData\\Local\\Programs\\Python\\Python311\\Lib\\site-packages\\langchain_google_genai\\_genai_extension.py\", line 293, in build_generative_async_service\n    return v1betaGenerativeServiceAsyncClient(**config)\n           ^^^^^^^^^^^^^^^^^^^^^^^^^^^^^^^^^^^^^^^^^^^^\n  File \"C:\\Users\\pc\\AppData\\Local\\Programs\\Python\\Python311\\Lib\\site-packages\\google\\ai\\generativelanguage_v1beta\\services\\generative_service\\async_client.py\", line 276, in __init__\n    self._client = GenerativeServiceClient(\n                   ^^^^^^^^^^^^^^^^^^^^^^^^\n  File \"C:\\Users\\pc\\AppData\\Local\\Programs\\Python\\Python311\\Lib\\site-packages\\google\\ai\\generativelanguage_v1beta\\services\\generative_service\\client.py\", line 697, in __init__\n    self._transport = transport_init(\n                      ^^^^^^^^^^^^^^^\n  File \"C:\\Users\\pc\\AppData\\Local\\Programs\\Python\\Python311\\Lib\\site-packages\\google\\ai\\generativelanguage_v1beta\\services\\generative_service\\transports\\grpc_asyncio.py\", line 297, in __init__\n    self._grpc_channel = channel_init(\n                         ^^^^^^^^^^^^^\n  File \"C:\\Users\\pc\\AppData\\Local\\Programs\\Python\\Python311\\Lib\\site-packages\\google\\ai\\generativelanguage_v1beta\\services\\generative_service\\transports\\grpc_asyncio.py\", line 165, in create_channel\n    return grpc_helpers_async.create_channel(\n           ^^^^^^^^^^^^^^^^^^^^^^^^^^^^^^^^^^\n  File \"C:\\Users\\pc\\AppData\\Local\\Programs\\Python\\Python311\\Lib\\site-packages\\google\\api_core\\grpc_helpers_async.py\", line 302, in create_channel\n    return aio.secure_channel(\n           ^^^^^^^^^^^^^^^^^^^\n  File \"C:\\Users\\pc\\AppData\\Local\\Programs\\Python\\Python311\\Lib\\site-packages\\grpc\\aio\\_channel.py\", line 621, in secure_channel\n    return Channel(\n           ^^^^^^^^\n  File \"C:\\Users\\pc\\AppData\\Local\\Programs\\Python\\Python311\\Lib\\site-packages\\grpc\\aio\\_channel.py\", line 367, in __init__\n    self._loop = cygrpc.get_working_loop()\n                 ^^^^^^^^^^^^^^^^^^^^^^^^^\n  File \"src\\\\python\\\\grpcio\\\\grpc\\\\_cython\\\\_cygrpc/aio/common.pyx.pxi\", line 186, in grpc._cython.cygrpc.get_working_loop\n  File \"src\\\\python\\\\grpcio\\\\grpc\\\\_cython\\\\_cygrpc/aio/common.pyx.pxi\", line 190, in grpc._cython.cygrpc.get_working_loop\n  File \"C:\\Users\\pc\\AppData\\Local\\Programs\\Python\\Python311\\Lib\\asyncio\\events.py\", line 677, in get_event_loop\n    raise RuntimeError('There is no current event loop in thread %r.'\nRuntimeError: There is no current event loop in thread 'Thread-3 (process_request_thread)'.\nDuring task with name 'prepare' and id '3641e309-8b0f-fff4-f863-86658eb7c90e'\n"}
{"timestamp": "2025-08-06T16:45:00.564909+00:00", "api_endpoint": "/api/rag_chat", "error": "There is no current event loop in thread 'Thread-2 (process_request_thread)'.", "traceback": "Traceback (most recent call last):\n  File \"src\\\\python\\\\grpcio\\\\grpc\\\\_cython\\\\_cygrpc/aio/common.pyx.pxi\", line 184, in grpc._cython.cygrpc.get_working_loop\nRuntimeError: no running event loop\n\nDuring handling of the above exception, another exception occurred:\n\nTraceback (most recent call last):\n  File \"c:\\Users\\pc\\Desktop\\Memordo\\py\\app.py\", line 67, in rag_chat\n    result = rag_app.invoke(inputs)\n             ^^^^^^^^^^^^^^^^^^^^^^\n  File \"C:\\Users\\pc\\AppData\\Local\\Programs\\Python\\Python311\\Lib\\site-packages\\langgraph\\pregel\\main.py\", line 3015, in invoke\n    for chunk in self.stream(\n  File \"C:\\Users\\pc\\AppData\\Local\\Programs\\Python\\Python311\\Lib\\site-packages\\langgraph\\pregel\\main.py\", line 2642, in stream\n    for _ in runner.tick(\n  File \"C:\\Users\\pc\\AppData\\Local\\Programs\\Python\\Python311\\Lib\\site-packages\\langgraph\\pregel\\_runner.py\", line 162, in tick\n    run_with_retry(\n  File \"C:\\Users\\pc\\AppData\\Local\\Programs\\Python\\Python311\\Lib\\site-packages\\langgraph\\pregel\\_retry.py\", line 42, in run_with_retry\n    return task.proc.invoke(task.input, config)\n           ^^^^^^^^^^^^^^^^^^^^^^^^^^^^^^^^^^^^\n  File \"C:\\Users\\pc\\AppData\\Local\\Programs\\Python\\Python311\\Lib\\site-packages\\langgraph\\_internal\\_runnable.py\", line 657, in invoke\n    input = context.run(step.invoke, input, config, **kwargs)\n            ^^^^^^^^^^^^^^^^^^^^^^^^^^^^^^^^^^^^^^^^^^^^^^^^^\n  File \"C:\\Users\\pc\\AppData\\Local\\Programs\\Python\\Python311\\Lib\\site-packages\\langgraph\\_internal\\_runnable.py\", line 401, in invoke\n    ret = self.func(*args, **kwargs)\n          ^^^^^^^^^^^^^^^^^^^^^^^^^^\n  File \"c:\\Users\\pc\\Desktop\\Memordo\\py\\rag_workflow.py\", line 54, in prepare_retrieval\n    embedding_function = GoogleGenerativeAIEmbeddings(\n                         ^^^^^^^^^^^^^^^^^^^^^^^^^^^^^\n  File \"C:\\Users\\pc\\AppData\\Local\\Programs\\Python\\Python311\\Lib\\site-packages\\pydantic\\main.py\", line 214, in __init__\n    validated_self = self.__pydantic_validator__.validate_python(data, self_instance=self)\n                     ^^^^^^^^^^^^^^^^^^^^^^^^^^^^^^^^^^^^^^^^^^^^^^^^^^^^^^^^^^^^^^^^^^^^^\n  File \"C:\\Users\\pc\\AppData\\Local\\Programs\\Python\\Python311\\Lib\\site-packages\\langchain_google_genai\\embeddings.py\", line 110, in validate_environment\n    self.async_client = build_generative_async_service(\n                        ^^^^^^^^^^^^^^^^^^^^^^^^^^^^^^^\n  File \"C:\\Users\\pc\\AppData\\Local\\Programs\\Python\\Python311\\Lib\\site-packages\\langchain_google_genai\\_genai_extension.py\", line 293, in build_generative_async_service\n    return v1betaGenerativeServiceAsyncClient(**config)\n           ^^^^^^^^^^^^^^^^^^^^^^^^^^^^^^^^^^^^^^^^^^^^\n  File \"C:\\Users\\pc\\AppData\\Local\\Programs\\Python\\Python311\\Lib\\site-packages\\google\\ai\\generativelanguage_v1beta\\services\\generative_service\\async_client.py\", line 276, in __init__\n    self._client = GenerativeServiceClient(\n                   ^^^^^^^^^^^^^^^^^^^^^^^^\n  File \"C:\\Users\\pc\\AppData\\Local\\Programs\\Python\\Python311\\Lib\\site-packages\\google\\ai\\generativelanguage_v1beta\\services\\generative_service\\client.py\", line 697, in __init__\n    self._transport = transport_init(\n                      ^^^^^^^^^^^^^^^\n  File \"C:\\Users\\pc\\AppData\\Local\\Programs\\Python\\Python311\\Lib\\site-packages\\google\\ai\\generativelanguage_v1beta\\services\\generative_service\\transports\\grpc_asyncio.py\", line 297, in __init__\n    self._grpc_channel = channel_init(\n                         ^^^^^^^^^^^^^\n  File \"C:\\Users\\pc\\AppData\\Local\\Programs\\Python\\Python311\\Lib\\site-packages\\google\\ai\\generativelanguage_v1beta\\services\\generative_service\\transports\\grpc_asyncio.py\", line 165, in create_channel\n    return grpc_helpers_async.create_channel(\n           ^^^^^^^^^^^^^^^^^^^^^^^^^^^^^^^^^^\n  File \"C:\\Users\\pc\\AppData\\Local\\Programs\\Python\\Python311\\Lib\\site-packages\\google\\api_core\\grpc_helpers_async.py\", line 302, in create_channel\n    return aio.secure_channel(\n           ^^^^^^^^^^^^^^^^^^^\n  File \"C:\\Users\\pc\\AppData\\Local\\Programs\\Python\\Python311\\Lib\\site-packages\\grpc\\aio\\_channel.py\", line 621, in secure_channel\n    return Channel(\n           ^^^^^^^^\n  File \"C:\\Users\\pc\\AppData\\Local\\Programs\\Python\\Python311\\Lib\\site-packages\\grpc\\aio\\_channel.py\", line 367, in __init__\n    self._loop = cygrpc.get_working_loop()\n                 ^^^^^^^^^^^^^^^^^^^^^^^^^\n  File \"src\\\\python\\\\grpcio\\\\grpc\\\\_cython\\\\_cygrpc/aio/common.pyx.pxi\", line 186, in grpc._cython.cygrpc.get_working_loop\n  File \"src\\\\python\\\\grpcio\\\\grpc\\\\_cython\\\\_cygrpc/aio/common.pyx.pxi\", line 190, in grpc._cython.cygrpc.get_working_loop\n  File \"C:\\Users\\pc\\AppData\\Local\\Programs\\Python\\Python311\\Lib\\asyncio\\events.py\", line 677, in get_event_loop\n    raise RuntimeError('There is no current event loop in thread %r.'\nRuntimeError: There is no current event loop in thread 'Thread-2 (process_request_thread)'.\nDuring task with name 'prepare' and id '75243c79-527a-5c62-d3fe-4694e3f12f26'\n"}
{"timestamp": "2025-08-06T16:47:57.359575+00:00", "api_endpoint": "/api/rag_chat", "error": "404 models/gemini-pro is not found for API version v1beta, or is not supported for generateContent. Call ListModels to see the list of available models and their supported methods.", "traceback": "Traceback (most recent call last):\n  File \"c:\\Users\\pc\\Desktop\\Memordo\\py\\app.py\", line 78, in rag_chat\n    result = rag_app.invoke(inputs)\n             ^^^^^^^^^^^^^^^^^^^^^^\n  File \"C:\\Users\\pc\\AppData\\Local\\Programs\\Python\\Python311\\Lib\\site-packages\\langgraph\\pregel\\main.py\", line 3015, in invoke\n    for chunk in self.stream(\n  File \"C:\\Users\\pc\\AppData\\Local\\Programs\\Python\\Python311\\Lib\\site-packages\\langgraph\\pregel\\main.py\", line 2642, in stream\n    for _ in runner.tick(\n  File \"C:\\Users\\pc\\AppData\\Local\\Programs\\Python\\Python311\\Lib\\site-packages\\langgraph\\pregel\\_runner.py\", line 162, in tick\n    run_with_retry(\n  File \"C:\\Users\\pc\\AppData\\Local\\Programs\\Python\\Python311\\Lib\\site-packages\\langgraph\\pregel\\_retry.py\", line 42, in run_with_retry\n    return task.proc.invoke(task.input, config)\n           ^^^^^^^^^^^^^^^^^^^^^^^^^^^^^^^^^^^^\n  File \"C:\\Users\\pc\\AppData\\Local\\Programs\\Python\\Python311\\Lib\\site-packages\\langgraph\\_internal\\_runnable.py\", line 657, in invoke\n    input = context.run(step.invoke, input, config, **kwargs)\n            ^^^^^^^^^^^^^^^^^^^^^^^^^^^^^^^^^^^^^^^^^^^^^^^^^\n  File \"C:\\Users\\pc\\AppData\\Local\\Programs\\Python\\Python311\\Lib\\site-packages\\langgraph\\_internal\\_runnable.py\", line 401, in invoke\n    ret = self.func(*args, **kwargs)\n          ^^^^^^^^^^^^^^^^^^^^^^^^^^\n  File \"c:\\Users\\pc\\Desktop\\Memordo\\py\\rag_workflow.py\", line 147, in generate_answer\n    answer = chain.invoke({\"context\": context_text, \"question\": question})\n             ^^^^^^^^^^^^^^^^^^^^^^^^^^^^^^^^^^^^^^^^^^^^^^^^^^^^^^^^^^^^^\n  File \"C:\\Users\\pc\\AppData\\Local\\Programs\\Python\\Python311\\Lib\\site-packages\\langchain_core\\runnables\\base.py\", line 3046, in invoke\n    input_ = context.run(step.invoke, input_, config)\n             ^^^^^^^^^^^^^^^^^^^^^^^^^^^^^^^^^^^^^^^^\n  File \"C:\\Users\\pc\\AppData\\Local\\Programs\\Python\\Python311\\Lib\\site-packages\\langchain_google_genai\\chat_models.py\", line 1488, in invoke\n    return super().invoke(input, config, stop=stop, **kwargs)\n           ^^^^^^^^^^^^^^^^^^^^^^^^^^^^^^^^^^^^^^^^^^^^^^^^^^\n  File \"C:\\Users\\pc\\AppData\\Local\\Programs\\Python\\Python311\\Lib\\site-packages\\langchain_core\\language_models\\chat_models.py\", line 395, in invoke\n    self.generate_prompt(\n  File \"C:\\Users\\pc\\AppData\\Local\\Programs\\Python\\Python311\\Lib\\site-packages\\langchain_core\\language_models\\chat_models.py\", line 980, in generate_prompt\n    return self.generate(prompt_messages, stop=stop, callbacks=callbacks, **kwargs)\n           ^^^^^^^^^^^^^^^^^^^^^^^^^^^^^^^^^^^^^^^^^^^^^^^^^^^^^^^^^^^^^^^^^^^^^^^^\n  File \"C:\\Users\\pc\\AppData\\Local\\Programs\\Python\\Python311\\Lib\\site-packages\\langchain_core\\language_models\\chat_models.py\", line 799, in generate\n    self._generate_with_cache(\n  File \"C:\\Users\\pc\\AppData\\Local\\Programs\\Python\\Python311\\Lib\\site-packages\\langchain_core\\language_models\\chat_models.py\", line 1045, in _generate_with_cache\n    result = self._generate(\n             ^^^^^^^^^^^^^^^\n  File \"C:\\Users\\pc\\AppData\\Local\\Programs\\Python\\Python311\\Lib\\site-packages\\langchain_google_genai\\chat_models.py\", line 1595, in _generate\n    response: GenerateContentResponse = _chat_with_retry(\n                                        ^^^^^^^^^^^^^^^^^\n  File \"C:\\Users\\pc\\AppData\\Local\\Programs\\Python\\Python311\\Lib\\site-packages\\langchain_google_genai\\chat_models.py\", line 247, in _chat_with_retry\n    return _chat_with_retry(**params)\n           ^^^^^^^^^^^^^^^^^^^^^^^^^^\n  File \"C:\\Users\\pc\\AppData\\Local\\Programs\\Python\\Python311\\Lib\\site-packages\\tenacity\\__init__.py\", line 336, in wrapped_f\n    return copy(f, *args, **kw)\n           ^^^^^^^^^^^^^^^^^^^^\n  File \"C:\\Users\\pc\\AppData\\Local\\Programs\\Python\\Python311\\Lib\\site-packages\\tenacity\\__init__.py\", line 475, in __call__\n    do = self.iter(retry_state=retry_state)\n         ^^^^^^^^^^^^^^^^^^^^^^^^^^^^^^^^^^\n  File \"C:\\Users\\pc\\AppData\\Local\\Programs\\Python\\Python311\\Lib\\site-packages\\tenacity\\__init__.py\", line 376, in iter\n    result = action(retry_state)\n             ^^^^^^^^^^^^^^^^^^^\n  File \"C:\\Users\\pc\\AppData\\Local\\Programs\\Python\\Python311\\Lib\\site-packages\\tenacity\\__init__.py\", line 418, in exc_check\n    raise retry_exc.reraise()\n          ^^^^^^^^^^^^^^^^^^^\n  File \"C:\\Users\\pc\\AppData\\Local\\Programs\\Python\\Python311\\Lib\\site-packages\\tenacity\\__init__.py\", line 185, in reraise\n    raise self.last_attempt.result()\n          ^^^^^^^^^^^^^^^^^^^^^^^^^^\n  File \"C:\\Users\\pc\\AppData\\Local\\Programs\\Python\\Python311\\Lib\\concurrent\\futures\\_base.py\", line 449, in result\n    return self.__get_result()\n           ^^^^^^^^^^^^^^^^^^^\n  File \"C:\\Users\\pc\\AppData\\Local\\Programs\\Python\\Python311\\Lib\\concurrent\\futures\\_base.py\", line 401, in __get_result\n    raise self._exception\n  File \"C:\\Users\\pc\\AppData\\Local\\Programs\\Python\\Python311\\Lib\\site-packages\\tenacity\\__init__.py\", line 478, in __call__\n    result = fn(*args, **kwargs)\n             ^^^^^^^^^^^^^^^^^^^\n  File \"C:\\Users\\pc\\AppData\\Local\\Programs\\Python\\Python311\\Lib\\site-packages\\langchain_google_genai\\chat_models.py\", line 238, in _chat_with_retry\n    raise e\n  File \"C:\\Users\\pc\\AppData\\Local\\Programs\\Python\\Python311\\Lib\\site-packages\\langchain_google_genai\\chat_models.py\", line 216, in _chat_with_retry\n    return generation_method(**kwargs)\n           ^^^^^^^^^^^^^^^^^^^^^^^^^^^\n  File \"C:\\Users\\pc\\AppData\\Local\\Programs\\Python\\Python311\\Lib\\site-packages\\google\\ai\\generativelanguage_v1beta\\services\\generative_service\\client.py\", line 868, in generate_content\n    response = rpc(\n               ^^^^\n  File \"C:\\Users\\pc\\AppData\\Local\\Programs\\Python\\Python311\\Lib\\site-packages\\google\\api_core\\gapic_v1\\method.py\", line 131, in __call__\n    return wrapped_func(*args, **kwargs)\n           ^^^^^^^^^^^^^^^^^^^^^^^^^^^^^\n  File \"C:\\Users\\pc\\AppData\\Local\\Programs\\Python\\Python311\\Lib\\site-packages\\google\\api_core\\retry\\retry_unary.py\", line 293, in retry_wrapped_func\n    return retry_target(\n           ^^^^^^^^^^^^^\n  File \"C:\\Users\\pc\\AppData\\Local\\Programs\\Python\\Python311\\Lib\\site-packages\\google\\api_core\\retry\\retry_unary.py\", line 153, in retry_target\n    _retry_error_helper(\n  File \"C:\\Users\\pc\\AppData\\Local\\Programs\\Python\\Python311\\Lib\\site-packages\\google\\api_core\\retry\\retry_base.py\", line 212, in _retry_error_helper\n    raise final_exc from source_exc\n  File \"C:\\Users\\pc\\AppData\\Local\\Programs\\Python\\Python311\\Lib\\site-packages\\google\\api_core\\retry\\retry_unary.py\", line 144, in retry_target\n    result = target()\n             ^^^^^^^^\n  File \"C:\\Users\\pc\\AppData\\Local\\Programs\\Python\\Python311\\Lib\\site-packages\\google\\api_core\\timeout.py\", line 130, in func_with_timeout\n    return func(*args, **kwargs)\n           ^^^^^^^^^^^^^^^^^^^^^\n  File \"C:\\Users\\pc\\AppData\\Local\\Programs\\Python\\Python311\\Lib\\site-packages\\google\\api_core\\grpc_helpers.py\", line 78, in error_remapped_callable\n    raise exceptions.from_grpc_error(exc) from exc\ngoogle.api_core.exceptions.NotFound: 404 models/gemini-pro is not found for API version v1beta, or is not supported for generateContent. Call ListModels to see the list of available models and their supported methods.\nDuring task with name 'generate' and id '358817a4-b82b-1fd9-f5c7-3aef479f314b'\n"}
{"timestamp": "2025-08-06T16:51:12.437890+00:00", "api_endpoint": "/api/rag_chat", "input_query": "메모르도와 구글 드라이브 백업 계획에 대해서 알려줘 ", "output_answer": "죄송합니다. 제공된 노트에는 Memordo와 구글 드라이브 백업 계획에 대한 정보가 포함되어 있지 않습니다.  따라서 질문에 대한 답변을 드릴 수 없습니다.  \"오사카 식도락 여행 필수 코스.md\", \"도쿄 3박 4일 핵심 여행 계획.md\", \"홋카이도 겨울 풍경 사진 촬영 팁.md\" 세 개의 문서만 참고했습니다.", "final_context": "문서명: 오사카 식도락 여행 필수 코스.md\n내용:\n주제: 오사카 여행, 음식, 맛집, 도톤보리\n\n일본의 부엌이라 불리는 오사카는 맛있는 음식이 넘쳐나는 미식의 도시다. 오사카에 간다면 반드시 먹어봐야 할 음식 리스트와 추천 지역을 정리했다.\n\n1. 도톤보리: 오사카 음식 여행의 심장. 화려한 네온사인과 거대한 입체 간판들이 눈길을 끈다.\n\n타코야키: '앗치치혼포', '타코야키 와나카' 등 유명 가게들이 즐비하다. 가게마다 반죽과 소스의 맛이 미묘하게 다르니 비교해보는 재미가 있다.\n\n오코노미야키: '치보', '미즈노' 등 오랜 역사를 자랑하는 맛집들이 많다. 눈앞의 철판에서 직접 만들어주는 오코노미야키는 맛과 재미를 동시에 선사한다.\n\n라멘: '킨류라멘', '이치란라멘' 등 24시간 운영하는 곳이 많아 늦은 밤 출출할 때 찾기 좋다.\n\n2. 쿠로몬 시장: 신선한 해산물과 길거리 음식을 맛볼 수 있는 재래시장.\n\n가리비 구이 & 성게알: 즉석에서 구워주는 신선한 가리비와 달콤한 성게알은 꼭 먹어봐야 할 메뉴.\n\n참치 초밥: 신선한 참치를 저렴한 가격에 맛볼 수 있다.\n\n과일 꼬치: 제철 과일을 꼬치에 꽂아 팔아 식후 디저트로 안성맞춤이다.\n\n3. 신세카이: 복고풍 분위기가 물씬 풍기는 지역.\n\n쿠시카츠: 튀김 꼬치 요리인 쿠시카츠의 원조 지역. '다루마'가 가장 유명하며, 소스는 한 번만 찍어야 한다는 규칙을 잊지 말자.\n\n---\n\n문서명: 도쿄 3박 4일 핵심 여행 계획.md\n내용:\n주제: 도쿄 여행, 일정, 쇼핑, 관광\n\n1일차: 시부야 & 하라주쿠\n\n오후 2시: 나리타 공항 도착 후, 나리타 익스프레스를 타고 신주쿠역으로 이동.\n\n오후 4시: 호텔 체크인 후 짐 풀기.\n\n오후 5시: 시부야로 이동. 스크램블 교차로에서 인파 구경 및 사진 촬영. 하치코 동상 앞에서 기념사진.\n\n저녁 7시: 시부야 히카리에 또는 마크시티에서 저녁 식사. (추천: 이치란 라멘)\n\n저녁 9시: 최신 트렌드를 볼 수 있는 시부야 109, 디즈니 스토어 등 쇼핑.\n\n2일차: 아사쿠사 & 우에노\n\n오전 10시: 아사쿠사 센소지로 이동. 가미나리몬 앞에서 사진 찍고, 나카미세도리 상점가 구경.\n\n점심 12시: 아사쿠사 주변에서 몬자야키 또는 텐동 맛집 탐방.\n\n오후 2시: 스미다 강 유람선 탑승 또는 도쿄 스카이트리 전망대 관람.\n\n오후 4시: 우에노로 이동. 우에노 공원 산책 및 도쿄 국립 박물관 관람.\n\n저녁 6시: 아메요코 시장에서 길거리 음식 체험 및 저녁 식사.\n\n3일차: 지브리 미술관 & 신주쿠\n\n오전 10시: (사전 예약 필수) 미타카에 위치한 지브리 미술관으로 이동하여 관람.\n\n점심 1시: 기치조지 역 주변에서 점심 식사.\n\n오후 3시: 신주쿠로 복귀. 신주쿠 교엔에서 도심 속 자연 만끽.\n\n오후 5시: 도쿄 도청 전망대에 올라 무료로 도쿄 전경 감상.\n\n저녁 7시: 오모이데 요코초(추억의 골목)에서 야키토리와 맥주로 저녁 마무리.\n\n4일차: 귀국\n\n오전: 호텔 체크아웃 후, 신주쿠역에서 나리타 익스프레스로 공항 이동. 면세점 쇼핑 후 귀국\n\n---\n\n문서명: 홋카이도 겨울 풍경 사진 촬영 팁.md\n내용:\n주제: 홋카이도 여행, 겨울, 풍경, 사진 촬영\n\n겨울의 홋카이도는 눈과 얼음으로 뒤덮인 순백의 왕국이다. 동화 같은 설경을 사진에 제대로 담기 위한 몇 가지 팁을 소개한다.\n\n1. 노출 보정은 필수: 온통 하얀 눈밭을 찍을 때 카메라는 실제보다 어둡다고 판단하여 사진을 회색빛으로 찍는 경향이 있다. 이를 방지하려면 노출 보정 다이얼을 +1 또는 +1.5 스톱 정도 올려서 촬영해야 눈의 흰색이 제대로 표현된다.\n\n2. 화이트 밸런스 설정: 차가운 겨울의 느낌을 강조하고 싶다면 화이트 밸런스(WB)를 '형광등' 모드로 설정하여 푸른빛이 돌게 만들 수 있다. 반대로 따뜻한 새벽녘의 느낌을 살리고 싶다면 '그늘' 모드로 설정하여 붉은 기운을 더해보자.\n\n3. 비에이의 눈 덮인 언덕: 패치워크 로드와 파노라마 로드는 겨울 홋카이도 사진의 정수다. 광활한 언덕 위에 홀로 서 있는 '크리스마스 트리 나무'나 '세븐스타 나무'를 촬영할 때는 광각 렌즈를 사용하여 넓은 공간감을 표현하고, 망원 렌즈로 특정 나무만 압축하여 담아보는 등 다양한 시도가 필요하다.\n\n4. 삿포로 눈 축제 야경: 야경 촬영 시에는 삼각대가 필수다. ISO 감도를 낮게 설정하고 셔터 스피드를 길게 확보하여 노이즈 없이 선명한 조명과 얼음 조각을 담아내자."}
{"timestamp": "2025-08-06T16:51:50.246449+00:00", "api_endpoint": "/api/rag_chat", "input_query": "Memordo와 Google Drive 백업 연동 기획에 대해서 알려줘 ", "output_answer": "죄송합니다. 제공된 노트에는 Memordo와 Google Drive 백업 연동 기획에 대한 정보가 포함되어 있지 않습니다.  따라서 질문에 대한 답변을 드릴 수 없습니다.  \"오사카 식도락 여행 필수 코스.md\", \"도쿄 3박 4일 핵심 여행 계획.md\", \"홋카이도 겨울 풍경 사진 촬영 팁.md\" 세 개의 문서만 참고했습니다.", "final_context": "문서명: 오사카 식도락 여행 필수 코스.md\n내용:\n주제: 오사카 여행, 음식, 맛집, 도톤보리\n\n일본의 부엌이라 불리는 오사카는 맛있는 음식이 넘쳐나는 미식의 도시다. 오사카에 간다면 반드시 먹어봐야 할 음식 리스트와 추천 지역을 정리했다.\n\n1. 도톤보리: 오사카 음식 여행의 심장. 화려한 네온사인과 거대한 입체 간판들이 눈길을 끈다.\n\n타코야키: '앗치치혼포', '타코야키 와나카' 등 유명 가게들이 즐비하다. 가게마다 반죽과 소스의 맛이 미묘하게 다르니 비교해보는 재미가 있다.\n\n오코노미야키: '치보', '미즈노' 등 오랜 역사를 자랑하는 맛집들이 많다. 눈앞의 철판에서 직접 만들어주는 오코노미야키는 맛과 재미를 동시에 선사한다.\n\n라멘: '킨류라멘', '이치란라멘' 등 24시간 운영하는 곳이 많아 늦은 밤 출출할 때 찾기 좋다.\n\n2. 쿠로몬 시장: 신선한 해산물과 길거리 음식을 맛볼 수 있는 재래시장.\n\n가리비 구이 & 성게알: 즉석에서 구워주는 신선한 가리비와 달콤한 성게알은 꼭 먹어봐야 할 메뉴.\n\n참치 초밥: 신선한 참치를 저렴한 가격에 맛볼 수 있다.\n\n과일 꼬치: 제철 과일을 꼬치에 꽂아 팔아 식후 디저트로 안성맞춤이다.\n\n3. 신세카이: 복고풍 분위기가 물씬 풍기는 지역.\n\n쿠시카츠: 튀김 꼬치 요리인 쿠시카츠의 원조 지역. '다루마'가 가장 유명하며, 소스는 한 번만 찍어야 한다는 규칙을 잊지 말자.\n\n---\n\n문서명: 도쿄 3박 4일 핵심 여행 계획.md\n내용:\n주제: 도쿄 여행, 일정, 쇼핑, 관광\n\n1일차: 시부야 & 하라주쿠\n\n오후 2시: 나리타 공항 도착 후, 나리타 익스프레스를 타고 신주쿠역으로 이동.\n\n오후 4시: 호텔 체크인 후 짐 풀기.\n\n오후 5시: 시부야로 이동. 스크램블 교차로에서 인파 구경 및 사진 촬영. 하치코 동상 앞에서 기념사진.\n\n저녁 7시: 시부야 히카리에 또는 마크시티에서 저녁 식사. (추천: 이치란 라멘)\n\n저녁 9시: 최신 트렌드를 볼 수 있는 시부야 109, 디즈니 스토어 등 쇼핑.\n\n2일차: 아사쿠사 & 우에노\n\n오전 10시: 아사쿠사 센소지로 이동. 가미나리몬 앞에서 사진 찍고, 나카미세도리 상점가 구경.\n\n점심 12시: 아사쿠사 주변에서 몬자야키 또는 텐동 맛집 탐방.\n\n오후 2시: 스미다 강 유람선 탑승 또는 도쿄 스카이트리 전망대 관람.\n\n오후 4시: 우에노로 이동. 우에노 공원 산책 및 도쿄 국립 박물관 관람.\n\n저녁 6시: 아메요코 시장에서 길거리 음식 체험 및 저녁 식사.\n\n3일차: 지브리 미술관 & 신주쿠\n\n오전 10시: (사전 예약 필수) 미타카에 위치한 지브리 미술관으로 이동하여 관람.\n\n점심 1시: 기치조지 역 주변에서 점심 식사.\n\n오후 3시: 신주쿠로 복귀. 신주쿠 교엔에서 도심 속 자연 만끽.\n\n오후 5시: 도쿄 도청 전망대에 올라 무료로 도쿄 전경 감상.\n\n저녁 7시: 오모이데 요코초(추억의 골목)에서 야키토리와 맥주로 저녁 마무리.\n\n4일차: 귀국\n\n오전: 호텔 체크아웃 후, 신주쿠역에서 나리타 익스프레스로 공항 이동. 면세점 쇼핑 후 귀국\n\n---\n\n문서명: 홋카이도 겨울 풍경 사진 촬영 팁.md\n내용:\n주제: 홋카이도 여행, 겨울, 풍경, 사진 촬영\n\n겨울의 홋카이도는 눈과 얼음으로 뒤덮인 순백의 왕국이다. 동화 같은 설경을 사진에 제대로 담기 위한 몇 가지 팁을 소개한다.\n\n1. 노출 보정은 필수: 온통 하얀 눈밭을 찍을 때 카메라는 실제보다 어둡다고 판단하여 사진을 회색빛으로 찍는 경향이 있다. 이를 방지하려면 노출 보정 다이얼을 +1 또는 +1.5 스톱 정도 올려서 촬영해야 눈의 흰색이 제대로 표현된다.\n\n2. 화이트 밸런스 설정: 차가운 겨울의 느낌을 강조하고 싶다면 화이트 밸런스(WB)를 '형광등' 모드로 설정하여 푸른빛이 돌게 만들 수 있다. 반대로 따뜻한 새벽녘의 느낌을 살리고 싶다면 '그늘' 모드로 설정하여 붉은 기운을 더해보자.\n\n3. 비에이의 눈 덮인 언덕: 패치워크 로드와 파노라마 로드는 겨울 홋카이도 사진의 정수다. 광활한 언덕 위에 홀로 서 있는 '크리스마스 트리 나무'나 '세븐스타 나무'를 촬영할 때는 광각 렌즈를 사용하여 넓은 공간감을 표현하고, 망원 렌즈로 특정 나무만 압축하여 담아보는 등 다양한 시도가 필요하다.\n\n4. 삿포로 눈 축제 야경: 야경 촬영 시에는 삼각대가 필수다. ISO 감도를 낮게 설정하고 셔터 스피드를 길게 확보하여 노이즈 없이 선명한 조명과 얼음 조각을 담아내자."}
{"timestamp": "2025-08-06T16:56:21.194667+00:00", "api_endpoint": "/api/rag_chat", "input_query": "Memordo와 Google Drive 백업 연동 기획에 대해서 알려줘 ", "output_answer": "죄송합니다. 제공된 노트에는 Memordo와 Google Drive 백업 연동 기획에 대한 정보가 포함되어 있지 않습니다.  따라서 질문에 대한 답변을 드릴 수 없습니다.  \"오사카 식도락 여행 필수 코스.md\", \"도쿄 3박 4일 핵심 여행 계획.md\", \"홋카이도 겨울 풍경 사진 촬영 팁.md\" 세 개의 문서만 참고했습니다.", "final_context": "문서명: 오사카 식도락 여행 필수 코스.md\n내용:\n주제: 오사카 여행, 음식, 맛집, 도톤보리\n\n일본의 부엌이라 불리는 오사카는 맛있는 음식이 넘쳐나는 미식의 도시다. 오사카에 간다면 반드시 먹어봐야 할 음식 리스트와 추천 지역을 정리했다.\n\n1. 도톤보리: 오사카 음식 여행의 심장. 화려한 네온사인과 거대한 입체 간판들이 눈길을 끈다.\n\n타코야키: '앗치치혼포', '타코야키 와나카' 등 유명 가게들이 즐비하다. 가게마다 반죽과 소스의 맛이 미묘하게 다르니 비교해보는 재미가 있다.\n\n오코노미야키: '치보', '미즈노' 등 오랜 역사를 자랑하는 맛집들이 많다. 눈앞의 철판에서 직접 만들어주는 오코노미야키는 맛과 재미를 동시에 선사한다.\n\n라멘: '킨류라멘', '이치란라멘' 등 24시간 운영하는 곳이 많아 늦은 밤 출출할 때 찾기 좋다.\n\n2. 쿠로몬 시장: 신선한 해산물과 길거리 음식을 맛볼 수 있는 재래시장.\n\n가리비 구이 & 성게알: 즉석에서 구워주는 신선한 가리비와 달콤한 성게알은 꼭 먹어봐야 할 메뉴.\n\n참치 초밥: 신선한 참치를 저렴한 가격에 맛볼 수 있다.\n\n과일 꼬치: 제철 과일을 꼬치에 꽂아 팔아 식후 디저트로 안성맞춤이다.\n\n3. 신세카이: 복고풍 분위기가 물씬 풍기는 지역.\n\n쿠시카츠: 튀김 꼬치 요리인 쿠시카츠의 원조 지역. '다루마'가 가장 유명하며, 소스는 한 번만 찍어야 한다는 규칙을 잊지 말자.\n\n---\n\n문서명: 도쿄 3박 4일 핵심 여행 계획.md\n내용:\n주제: 도쿄 여행, 일정, 쇼핑, 관광\n\n1일차: 시부야 & 하라주쿠\n\n오후 2시: 나리타 공항 도착 후, 나리타 익스프레스를 타고 신주쿠역으로 이동.\n\n오후 4시: 호텔 체크인 후 짐 풀기.\n\n오후 5시: 시부야로 이동. 스크램블 교차로에서 인파 구경 및 사진 촬영. 하치코 동상 앞에서 기념사진.\n\n저녁 7시: 시부야 히카리에 또는 마크시티에서 저녁 식사. (추천: 이치란 라멘)\n\n저녁 9시: 최신 트렌드를 볼 수 있는 시부야 109, 디즈니 스토어 등 쇼핑.\n\n2일차: 아사쿠사 & 우에노\n\n오전 10시: 아사쿠사 센소지로 이동. 가미나리몬 앞에서 사진 찍고, 나카미세도리 상점가 구경.\n\n점심 12시: 아사쿠사 주변에서 몬자야키 또는 텐동 맛집 탐방.\n\n오후 2시: 스미다 강 유람선 탑승 또는 도쿄 스카이트리 전망대 관람.\n\n오후 4시: 우에노로 이동. 우에노 공원 산책 및 도쿄 국립 박물관 관람.\n\n저녁 6시: 아메요코 시장에서 길거리 음식 체험 및 저녁 식사.\n\n3일차: 지브리 미술관 & 신주쿠\n\n오전 10시: (사전 예약 필수) 미타카에 위치한 지브리 미술관으로 이동하여 관람.\n\n점심 1시: 기치조지 역 주변에서 점심 식사.\n\n오후 3시: 신주쿠로 복귀. 신주쿠 교엔에서 도심 속 자연 만끽.\n\n오후 5시: 도쿄 도청 전망대에 올라 무료로 도쿄 전경 감상.\n\n저녁 7시: 오모이데 요코초(추억의 골목)에서 야키토리와 맥주로 저녁 마무리.\n\n4일차: 귀국\n\n오전: 호텔 체크아웃 후, 신주쿠역에서 나리타 익스프레스로 공항 이동. 면세점 쇼핑 후 귀국\n\n---\n\n문서명: 홋카이도 겨울 풍경 사진 촬영 팁.md\n내용:\n주제: 홋카이도 여행, 겨울, 풍경, 사진 촬영\n\n겨울의 홋카이도는 눈과 얼음으로 뒤덮인 순백의 왕국이다. 동화 같은 설경을 사진에 제대로 담기 위한 몇 가지 팁을 소개한다.\n\n1. 노출 보정은 필수: 온통 하얀 눈밭을 찍을 때 카메라는 실제보다 어둡다고 판단하여 사진을 회색빛으로 찍는 경향이 있다. 이를 방지하려면 노출 보정 다이얼을 +1 또는 +1.5 스톱 정도 올려서 촬영해야 눈의 흰색이 제대로 표현된다.\n\n2. 화이트 밸런스 설정: 차가운 겨울의 느낌을 강조하고 싶다면 화이트 밸런스(WB)를 '형광등' 모드로 설정하여 푸른빛이 돌게 만들 수 있다. 반대로 따뜻한 새벽녘의 느낌을 살리고 싶다면 '그늘' 모드로 설정하여 붉은 기운을 더해보자.\n\n3. 비에이의 눈 덮인 언덕: 패치워크 로드와 파노라마 로드는 겨울 홋카이도 사진의 정수다. 광활한 언덕 위에 홀로 서 있는 '크리스마스 트리 나무'나 '세븐스타 나무'를 촬영할 때는 광각 렌즈를 사용하여 넓은 공간감을 표현하고, 망원 렌즈로 특정 나무만 압축하여 담아보는 등 다양한 시도가 필요하다.\n\n4. 삿포로 눈 축제 야경: 야경 촬영 시에는 삼각대가 필수다. ISO 감도를 낮게 설정하고 셔터 스피드를 길게 확보하여 노이즈 없이 선명한 조명과 얼음 조각을 담아내자."}
